<sdf version='1.7'>
  <model name='minimal_robot'>
    <link name='base_link'>
      <inertial>
        <pose>0 0 0.05 0 -0 0</pose>
        <mass>1</mass>
        <inertia>
          <ixx>0.01</ixx>
          <ixy>0</ixy>
          <ixz>0</ixz>
          <iyy>0.01</iyy>
          <iyz>0</iyz>
          <izz>0.01</izz>
        </inertia>
      </inertial>
      <collision name='base_link_collision'>
        <pose>0 0 0.05 0 -0 0</pose>
        <geometry>
          <box>
            <size>0.3 0.3 0.1</size>
          </box>
        </geometry>
      </collision>
      <visual name='base_link_visual'>
        <pose>0 0 0.05 0 -0 0</pose>
        <geometry>
          <box>
            <size>0.3 0.3 0.1</size>
          </box>
        </geometry>
      </visual>
    </link>
    <joint name='joint1' type='revolute'>
      <pose relative_to='base_link'>0 0 0.1 0 -0 0</pose>
      <parent>base_link</parent>
      <child>link1</child>
      <axis>
        <xyz>0 0 1</xyz>
        <limit>
          <lower>-3.14</lower>
          <upper>3.14</upper>
          <effort>10</effort>
          <velocity>5</velocity>
        </limit>
        <dynamics>
          <damping>0.1</damping>
          <friction>0</friction>
          <spring_reference>0</spring_reference>
          <spring_stiffness>0</spring_stiffness>
        </dynamics>
      </axis>
    </joint>
    <link name='link1'>
      <pose relative_to='joint1'>0 0 0 0 -0 0</pose>
      <inertial>
        <pose>0 0 0.25 0 -0 0</pose>
        <mass>1</mass>
        <inertia>
          <ixx>0.02</ixx>
          <ixy>0</ixy>
          <ixz>0</ixz>
          <iyy>0.02</iyy>
          <iyz>0</iyz>
          <izz>0.02</izz>
        </inertia>
      </inertial>
      <collision name='link1_collision'>
        <pose>0 0 0.25 0 -0 0</pose>
        <geometry>
          <box>
            <size>0.1 0.1 0.5</size>
          </box>
        </geometry>
      </collision>
      <visual name='link1_visual'>
        <pose>0 0 0.25 0 -0 0</pose>
        <geometry>
          <box>
            <size>0.1 0.1 0.5</size>
          </box>
        </geometry>
      </visual>
    </link>
  </model>
</sdf>
